<?xml version="1.0"?>
<!--
	base
	laser:hokuyo
	IMU
-->
<robot name="smartcar" xmlns:xacro="http://www.ros.org/wiki/xacro" >

	<xacro:property name="width" value="0.2" />
  <xacro:property name="leglen" value="0.6" />
  <xacro:property name="polelen" value="0.2" />
  <xacro:property name="bodylen" value="0.6" />
  <xacro:property name="baselen" value="0.4" />
  <xacro:property name="wheeldiam" value="0.04" />
  <xacro:property name="pi" value="3.1415" />

 <xacro:macro name="default_inertial" params="mass">
    <inertial>
      <mass value="${mass}" />
      <inertia ixx="1.0" ixy="0.0" ixz="0.0" iyy="1.0" iyz="0.0" izz="1.0" />
    </inertial>	
 </xacro:macro>

<link name="base_link">
    <visual>
      <geometry>
        <box size=".25 0.16 .05"/>
    </geometry>
    <origin rpy="0 0 1.57075" xyz="0 0 0"/>
    <material name="blue">
        <color rgba="0 0 .8 1"/>
    </material>
    </visual>
    <collision>
      <geometry>
      <box size=".25 0.16 .05"/>
      </geometry>
    </collision>
    <xacro:default_inertial mass="10"/>
 </link>

 <link name="right_front_wheel">
    <visual>
      <geometry>
        <cylinder length=".02" radius="0.025"/>
      </geometry>
      <material name="black">
        <color rgba="0 0 0 1"/>
      </material>
    </visual>
    <collision>
      <origin xyz="0 0 0" rpy="0 0 0" />
      <geometry>
      <cylinder length=".02" radius="0.025"/>
      </geometry>
    </collision>
    <xacro:default_inertial mass="1"/>
  </link>

  <joint name="right_front_wheel_joint" type="continuous">
    <axis xyz="0 0 1"/>
    <parent link="base_link"/>
    <child link="right_front_wheel"/>
    <origin rpy="0 1.57075 0" xyz="0.08 0.1 -0.03"/>
    <limit effort="100" velocity="100"/>
    <joint_properties damping="0.0" friction="0.0"/>
  </joint>

  <link name="right_back_wheel">
    <visual>
      <geometry>
        <cylinder length=".02" radius="0.025"/>
      </geometry>
      <material name="black">
        <color rgba="0 0 0 1"/>
      </material>
    </visual>
    <collision>
      <origin xyz="0 0 0" rpy="0 0 0" />
      <geometry>
      <cylinder length=".02" radius="0.025"/>
      </geometry>
    </collision>
    <xacro:default_inertial mass="1"/>
  </link>

  <joint name="right_back_wheel_joint" type="continuous">
    <axis xyz="0 0 1"/>
    <parent link="base_link"/>
    <child link="right_back_wheel"/>
    <origin rpy="0 1.57075 0" xyz="0.08 -0.1 -0.03"/>
    <limit effort="100" velocity="100"/>
    <joint_properties damping="0.0" friction="0.0"/>
 </joint>

 <link name="left_front_wheel">
    <visual>
      <geometry>
        <cylinder length=".02" radius="0.025"/>
      </geometry>
      <material name="black">
        <color rgba="0 0 0 1"/>
      </material>
    </visual>
    <collision>
      <origin xyz="0 0 0" rpy="0 0 0" />
      <geometry>
      <cylinder length=".02" radius="0.025"/>
      </geometry>
    </collision>
    <xacro:default_inertial mass="1"/>
  </link>

  <joint name="left_front_wheel_joint" type="continuous">
    <axis xyz="0 0 1"/>
    <parent link="base_link"/>
    <child link="left_front_wheel"/>
    <origin rpy="0 1.57075 0" xyz="-0.08 0.1 -0.03"/>
    <limit effort="100" velocity="100"/>
    <joint_properties damping="0.0" friction="0.0"/>
  </joint>

  <link name="left_back_wheel">
    <visual>
      <geometry>
        <cylinder length=".02" radius="0.025"/>
      </geometry>
      <material name="black">
        <color rgba="0 0 0 1"/>
      </material>
    </visual>
    <collision>
      <origin xyz="0 0 0" rpy="0 0 0" />
      <geometry>
      <cylinder length=".02" radius="0.025"/>
      </geometry>
    </collision>
    <xacro:default_inertial mass="1"/>
  </link>

  <joint name="left_back_wheel_joint" type="continuous">
    <axis xyz="0 0 1"/>
    <parent link="base_link"/>
    <child link="left_back_wheel"/>
    <origin rpy="0 1.57075 0" xyz="-0.08 -0.1 -0.03"/>
    <limit effort="100" velocity="100"/>
    <joint_properties damping="0.0" friction="0.0"/>
  </joint>

  <link name="hokuyo_link">
    <visual>
      <geometry>
        <box size=".02 .03 .03"/>
      </geometry>
      <material name="white">
          <color rgba="1 1 1 1"/>
      </material>
    </visual>
    <collision>
      <origin xyz="0 0 0" rpy="${pi/2} 0 0" />
      <geometry>
      <box size=".02 .03 .03"/>
      </geometry>
    </collision>
    <xacro:default_inertial mass="1"/>
  </link>

  <joint name="tobox" type="fixed">
    <parent link="base_link"/>
    <child link="hokuyo_link"/>
    <origin xyz="0 0.08 0.025"/>
  </joint>


<gazebo reference="hokuyo_link">
        <sensor type="ray" name="head_hokuyo_sensor">
          <pose>0 0 0 0 0 0</pose>
          <visualize>false</visualize>
          <update_rate>40</update_rate>
          <ray>
            <scan>
              <horizontal>
                <samples>720</samples>
                <resolution>1</resolution>

                <min_angle>-1.570796</min_angle>

                <max_angle>1.570796</max_angle>

              </horizontal>

            </scan>

            <range>

              <min>0.10</min>

              <max>30.0</max>

              <resolution>0.01</resolution>

            </range>

            <noise>

              <type>gaussian</type>

              <!-- Noise parameters based on published spec for Hokuyo laser

                   achieving "+-30mm" accuracy at range < 10m.  A mean of 0.0m and

                   stddev of 0.01m will put 99.7% of samples within 0.03m of the true

                   reading. -->

              <mean>0.0</mean>

              <stddev>0.01</stddev>

            </noise>

          </ray>

          <plugin name="gazebo_ros_head_hokuyo_controller" filename="libgazebo_ros_laser.so">

            <topicName>/scan</topicName>

            <frameName>hokuyo_link</frameName>

          </plugin>

        </sensor>

</gazebo>

<!--xacro:include filename="$(find mygazebo)/urdf/laser_hokuyo.xacro"/-->
 
 

  <gazebo reference="base_link">
    <gravity>true</gravity>
    <sensor name="imu_sensor" type="imu">
      <always_on>true</always_on>
      <update_rate>100</update_rate>
      <visualize>true</visualize>
      <topic>__default_topic__</topic>
      <plugin filename="libgazebo_ros_imu_sensor.so" name="imu_plugin">
        <topicName>imu</topicName>
        <bodyName>base_link</bodyName>
        <updateRateHZ>10.0</updateRateHZ>
        <gaussianNoise>0.0</gaussianNoise>
        <xyzOffset>0 0 0</xyzOffset>
        <rpyOffset>0 0 0</rpyOffset>
        <frameName>base_link</frameName>
      </plugin>
      <pose>0 0 0 0 0 0</pose>
    </sensor>
  </gazebo>
    



  <gazebo>
        <plugin name="differential_drive_controller" filename="libgazebo_ros_diff_drive.so">
            <alwaysOn>true</alwaysOn>
            <updateRate>50.0</updateRate>
            <leftJoint>left_front_wheel_joint</leftJoint>
            <rightJoint>right_front_wheel_joint</rightJoint>
            <wheelSeparation>1.0</wheelSeparation>
            <wheelDiameter>0.5</wheelDiameter>
            <torque>1.0</torque>
            <commandTopic>cmd_vel</commandTopic>
            <odometryTopic>odom</odometryTopic>
            <odometryFrame>odom</odometryFrame>
            <robotBaseFrame>base_link</robotBaseFrame>
            <publishWheelTF>true</publishWheelTF>
            <publishWheelJointState>true</publishWheelJointState>
            <legecyMode>false</legecyMode>
            <wheelAcceleration>1</wheelAcceleration>
        </plugin>
    </gazebo>

<transmission name="left_front_trans">
  <type>transmission_interface/SimpleTransmission</type>
  <joint name="left_front_wheel_joint">
    <hardwareInterface>EffortJointInterface</hardwareInterface>
  </joint>
  <actuator name="left_front_wheel_joint_motor">
    <mechanicalReduction>50</mechanicalReduction>
    <hardwareInterface>EffortJointInterface</hardwareInterface>
  </actuator>
</transmission>

<transmission name="right_front_trans">
  <type>transmission_interface/SimpleTransmission</type>
  <joint name="right_front_wheel_joint">
    <hardwareInterface>EffortJointInterface</hardwareInterface>
  </joint>
  <actuator name="right_front_wheel_joint_motor">
    <mechanicalReduction>50</mechanicalReduction>
    <hardwareInterface>EffortJointInterface</hardwareInterface>
  </actuator>
</transmission>

  
<!-- ros_control plugin -->
<gazebo>
    <plugin name="gazebo_ros_control" filename="libgazebo_ros_control.so">
      <robotNamespace>/robot</robotNamespace>
    </plugin>
  </gazebo>
</robot>
